Workbook

Sheet Player Summary
A1: Player Summary
A4: Player Name | B4: Stewart Gibbs
A5: Player Sex | B5: Male
A6: Player Age | B6: 62
A8: Technical Skills | B8: Attribute | C8: Level | D8: Standard | E8: Serve & Return | F8: Attribute | G8: Level | H8: Standard
B9: ='Technical Skills'!A3 -> Forehand | C9: ='Technical Skills'!B3 -> Advanced | D9: ='Technical Skills'!C3 -> 4 - Proficient | F9: ='Serve & Return'!A3 -> Shot Selection | G9: ='Serve & Return'!B3 -> Advanced | H9: ='Serve & Return'!C3 -> 4 - Proficient
B10: ='Technical Skills'!A8 -> Backhand | C10: ='Technical Skills'!B8 -> Advanced | D10: ='Technical Skills'!C8 -> 4 - Proficient | F10: ='Serve & Return'!A8 -> Second Serve Reliability | G10: ='Serve & Return'!B8 -> Advanced | H10: ='Serve & Return'!C8 -> 4 - Proficient
B11: ='Technical Skills'!A13 -> Serve | C11: ='Technical Skills'!B13 -> Advanced | D11: ='Technical Skills'!C13 -> 4 - Proficient | F11: ='Serve & Return'!A13 -> Serve Variation | G11: ='Serve & Return'!B13 -> Advanced | H11: ='Serve & Return'!C13 -> 4 - Proficient
B12: ='Technical Skills'!A18 -> Volley | C12: ='Technical Skills'!B18 -> Advanced | D12: ='Technical Skills'!C18 -> 2 - Developing | F12: ='Serve & Return'!A18 -> Return Positioning | G12: ='Serve & Return'!B18 -> Advanced | H12: ='Serve & Return'!C18 -> 4 - Proficient
B13: ='Technical Skills'!A23 -> Overhead Smash | C13: ='Technical Skills'!B23 -> Advanced | D13: ='Technical Skills'!C23 -> 3 - Competent | F13: ='Serve & Return'!A23 -> Return Strategies | G13: ='Serve & Return'!B23 -> Advanced | H13: ='Serve & Return'!C23 -> 4 - Proficient
B14: ='Technical Skills'!A28 -> Return of Serve | C14: ='Technical Skills'!B28 -> Advanced | D14: ='Technical Skills'!C28 -> 4 - Proficient
B15: ='Technical Skills'!A33 -> Specialty Shots | C15: ='Technical Skills'!B33 -> Beginner | D15: ='Technical Skills'!C33 -> 2 - Developing
A17: Footwork & Movement | B17: Attribute | C17: Level | D17: Standard | E17: Tactical Awarenes | F17: Attribute | G17: Level | H17: Standard
B18: ='Footwork & Movement'!A3 -> Split-step Timing | C18: ='Footwork & Movement'!B3 -> Intermediate | D18: ='Footwork & Movement'!C3 -> 3 - Competent | F18: ='Tactical Awareness'!A3 -> Shot Selection | G18: ='Tactical Awareness'!B3 -> Intermediate | H18: ='Tactical Awareness'!C3 -> 4 - Proficient
B19: ='Footwork & Movement'!A8 -> Recovery Steps | C19: ='Footwork & Movement'!B8 -> Intermediate | D19: ='Footwork & Movement'!C8 -> 3 - Competent | F19: ='Tactical Awareness'!A8 -> Point Construction | G19: ='Tactical Awareness'!B8 -> Beginner | H19: ='Tactical Awareness'!C8 -> 1 - Basic
B20: ='Footwork & Movement'!A13 -> Lateral Movement | C20: ='Footwork & Movement'!B13 -> Intermediate | D20: ='Footwork & Movement'!C13 -> 4 - Proficient | F20: ='Tactical Awareness'!A13 -> Adapting to Opponent | G20: ='Tactical Awareness'!B13 -> Beginner | H20: ='Tactical Awareness'!C13 -> 2 - Developing
B21: ='Footwork & Movement'!A18 -> Forward/Backward Movement | C21: ='Footwork & Movement'!B18 -> Intermediate | D21: ='Footwork & Movement'!C18 -> 2 - Developing | F21: ='Tactical Awareness'!A18 -> Playing to Surfaces | G21: ='Tactical Awareness'!B18 -> Beginner | H21: ='Tactical Awareness'!C18 -> 2 - Developing
B22: ='Footwork & Movement'!A23 -> Balance and Posture | C22: ='Footwork & Movement'!B23 -> Intermediate | D22: ='Footwork & Movement'!C23 -> 3 - Competent | F22: ='Tactical Awareness'!A23 -> Doubles Tactics | G22: ='Tactical Awareness'!B23 -> Beginner | H22: ='Tactical Awareness'!C23 -> 2 - Developing
A24: Creativity & Variety | B24: Attribute | C24: Level | D24: Standard | E24: Match Strategy | F24: Attribute | G24: Level | H24: Standard
B25: ='Creativity & Variety'!A3 -> Developing Spins | C25: ='Creativity & Variety'!B3 -> Beginner | D25: ='Creativity & Variety'!C3 -> 4 - Proficient | F25: ='Match Strategy'!A3 -> Pre-match Planning | G25: ='Match Strategy'!B3 -> Beginner | H25: ='Match Strategy'!C3 -> 4 - Proficient
B26: ='Creativity & Variety'!A8 -> Using Angles | C26: ='Creativity & Variety'!B8 -> Beginner | D26: ='Creativity & Variety'!C8 -> 1 - Basic | F26: ='Match Strategy'!A8 -> In-match Adjustments | G26: ='Match Strategy'!B8 -> Beginner | H26: ='Match Strategy'!C8 -> 1 - Basic
B27: ='Creativity & Variety'!A13 -> Improvisation | C27: ='Creativity & Variety'!B13 -> Beginner | D27: ='Creativity & Variety'!C13 -> 2 - Developing | F27: ='Match Strategy'!A13 -> Surface-specific Strategies | G27: ='Match Strategy'!B13 -> Beginner | H27: ='Match Strategy'!C13 -> 2 - Developing
B28: ='Creativity & Variety'!A18 -> Trick Shots | C28: ='Creativity & Variety'!B18 -> Beginner | D28: ='Creativity & Variety'!C18 -> 2 - Developing | F28: ='Match Strategy'!A18 -> Singles vs Doubles Approaches | G28: ='Match Strategy'!B18 -> Beginner | H28: ='Match Strategy'!C18 -> 2 - Developing
B29: ='Creativity & Variety'!A23 -> Variety in Rally Play | C29: ='Creativity & Variety'!B23 -> Beginner | D29: ='Creativity & Variety'!C23 -> 2 - Developing | F29: ='Match Strategy'!A23 -> Closing Out Matches | G29: ='Match Strategy'!B23 -> Beginner | H29: ='Match Strategy'!C23 -> 2 - Developing
A31: Competitive Experience | B31: Attribute | C31: Level | D31: Standard | E31: Physical Fitness | F31: Attribute | G31: Level | H31: Standard
B32: ='Competitive Experience'!A3 -> Tournament Exposure | C32: ='Competitive Experience'!B3 -> Beginner | D32: ='Competitive Experience'!C3 -> 4 - Proficient | F32: ='Physical Fitness'!A3 -> Strength | G32: ='Physical Fitness'!B3 -> Beginner | H32: ='Physical Fitness'!C3 -> 4 - Proficient
B33: ='Competitive Experience'!A8 -> Match-play Practice | C33: ='Competitive Experience'!B8 -> Beginner | D33: ='Competitive Experience'!C8 -> 1 - Basic | F33: ='Physical Fitness'!A8 -> Endurance | G33: ='Physical Fitness'!B8 -> Beginner | H33: ='Physical Fitness'!C8 -> 1 - Basic
B34: ='Competitive Experience'!A13 -> Handling Pressure Situations | C34: ='Competitive Experience'!B13 -> Beginner | D34: ='Competitive Experience'!C13 -> 2 - Developing | F34: ='Physical Fitness'!A13 -> Speed | G34: ='Physical Fitness'!B13 -> Beginner | H34: ='Physical Fitness'!C13 -> 2 - Developing
B35: ='Competitive Experience'!A18 -> Learning from Wins/Losses | C35: ='Competitive Experience'!B18 -> Beginner | D35: ='Competitive Experience'!C18 -> 2 - Developing | F35: ='Physical Fitness'!A18 -> Agility | G35: ='Physical Fitness'!B18 -> Beginner | H35: ='Physical Fitness'!C18 -> 2 - Developing
B36: ='Competitive Experience'!A23 -> Match Consistency | C36: ='Competitive Experience'!B23 -> Beginner | D36: ='Competitive Experience'!C23 -> 2 - Developing | F36: ='Physical Fitness'!A23 -> Flexibility & Mobility | G36: ='Physical Fitness'!B23 -> Beginner | H36: ='Physical Fitness'!C23 -> 2 - Developing
A38: Mental Toughness | B38: Attribute | C38: Level | D38: Standard | E38: Recovery & Injury Prevention | F38: Attribute | G38: Level | H38: Standard
B39: ='Mental Toughness'!A3 -> Focus and Concentration | C39: ='Mental Toughness'!B3 -> Beginner | D39: ='Mental Toughness'!C3 -> 4 - Proficient | F39: ='Recovery & Injury Prevention'!A3 -> Rest and Sleep | G39: ='Recovery & Injury Prevention'!B3 -> Beginner | H39: ='Recovery & Injury Prevention'!C3 -> 4 - Proficient
B40: ='Mental Toughness'!A8 -> Confidence Under Pressure | C40: ='Mental Toughness'!B8 -> Beginner | D40: ='Mental Toughness'!C8 -> 1 - Basic | F40: ='Recovery & Injury Prevention'!A8 -> Nutrition and Hydration | G40: ='Recovery & Injury Prevention'!B8 -> Beginner | H40: ='Recovery & Injury Prevention'!C8 -> 1 - Basic
B41: ='Mental Toughness'!A13 -> Emotional Control | C41: ='Mental Toughness'!B13 -> Beginner | D41: ='Mental Toughness'!C13 -> 2 - Developing | F41: ='Recovery & Injury Prevention'!A13 -> Warm-up/Cool-down | G41: ='Recovery & Injury Prevention'!B13 -> Beginner | H41: ='Recovery & Injury Prevention'!C13 -> 2 - Developing
B42: ='Mental Toughness'!A18 -> Resilience | C42: ='Mental Toughness'!B18 -> Beginner | D42: ='Mental Toughness'!C18 -> 2 - Developing | F42: ='Recovery & Injury Prevention'!A18 -> Prehab Exercises | G42: ='Recovery & Injury Prevention'!B18 -> Beginner | H42: ='Recovery & Injury Prevention'!C18 -> 2 - Developing
B43: ='Mental Toughness'!A23 -> Match Intensity | C43: ='Mental Toughness'!B23 -> Beginner | D43: ='Mental Toughness'!C23 -> 2 - Developing | F43: ='Recovery & Injury Prevention'!A23 -> Injury Management Awareness | G43: ='Recovery & Injury Prevention'!B23 -> Beginner | H43: ='Recovery & Injury Prevention'!C23 -> 2 - Developing
A45: Communication & Self-Reflection | B45: Attribute | C45: Level | D45: Standard | E45: Lifestyle & Discipline | F45: Attribute | G45: Level | H45: Standard
B46: ='Communication & Self-Reflection'!A3 -> Player–Coach Dialogue | C46: ='Communication & Self-Reflection'!B3 -> Beginner | D46: ='Communication & Self-Reflection'!C3 -> 4 - Proficient | F46: ='Lifestyle & Discipline'!A3 -> Time Management | G46: ='Lifestyle & Discipline'!B3 -> Beginner | H46: ='Lifestyle & Discipline'!C3 -> 4 - Proficient
B47: ='Communication & Self-Reflection'!A8 -> Journaling/Match Notes | C47: ='Communication & Self-Reflection'!B8 -> Beginner | D47: ='Communication & Self-Reflection'!C8 -> 1 - Basic | F47: ='Lifestyle & Discipline'!A8 -> Sleep Hygiene | G47: ='Lifestyle & Discipline'!B8 -> Beginner | H47: ='Lifestyle & Discipline'!C8 -> 1 - Basic
B48: ='Communication & Self-Reflection'!A13 -> Video Analysis | C48: ='Communication & Self-Reflection'!B13 -> Beginner | D48: ='Communication & Self-Reflection'!C13 -> 2 - Developing | F48: ='Lifestyle & Discipline'!A13 -> Nutrition Habits | G48: ='Lifestyle & Discipline'!B13 -> Beginner | H48: ='Lifestyle & Discipline'!C13 -> 2 - Developing
...

Sheet Technical Skills
A1: Technical Skills
A2: Attribute | B2: Level | C2: Rating (1-5) | D2: Strengths | E2: Weaknesses
A3: =Data!A12 -> Forehand | B3: Advanced | C3: 4 - Proficient | D3: Power and accuracy | E3: Lacks confidence on short approach ball
A4: Notes
A5: Displayed Attributes | D5: Attributes to Progress
A6: =IF(B3="Beginner",Data!B12,IF(B3="Intermediate",Data!C12,IF(B3="Advanced",Data!D12,"No Rating"))) -> Generates pace and spin at will; precise placement; uses inside-out/inside-in variations strategically. | D6: =IF(B3="Beginner",Data!C12,IF(B3="Intermediate",Data!D12,"No Rating")) -> No Rating
A7: Attribute | B7: Level | C7: Rating (1-5) | D7: Strengths | E7: Weaknesses
A8: =Data!A13 -> Backhand | B8: Advanced | C8: 4 - Proficient | E8: Tendency to straighten arms and rotate body
A9: Notes
A10: Displayed Attributes | D10: Attributes to Progress
A11: =IF(B8="Beginner",Data!B13,IF(B8="Intermediate",Data!C13,IF(B8="Advanced",Data!D13,"No Rating"))) -> Offensive weapon; mixes drive and slice seamlessly; controls angles and depth. | D11: =IF(B8="Beginner",Data!C13,IF(B8="Intermediate",Data!D13,"No Rating")) -> No Rating
A12: Attribute | B12: Level | C12: Rating (1-5) | D12: Strengths | E12: Weaknesses
A13: =Data!A14 -> Serve | B13: Advanced | C13: 4 - Proficient | D13: Consistency and power | E13: Lack of follow through
A14: Notes | B14: Follow the toss with tossing arm, stretch to the ball and follow through after service motion
A15: Displayed Attributes | D15: Attributes to Progress
A16: =IF(B13="Beginner",Data!B14,IF(B13="Intermediate",Data!C14,IF(B13="Advanced",Data!D14,"No Rating"))) -> Variety of serves (flat, slice, kick); tactical placement; uses serve to set up points. | D16: =IF(B13="Beginner",Data!C14,IF(B13="Intermediate",Data!D14,"No Rating")) -> No Rating
A17: Attribute | B17: Level | C17: Rating (1-5) | D17: Strengths | E17: Weaknesses
A18: =Data!A15 -> Volley | B18: Advanced | C18: 2 - Developing | E18: Doesn't move forward, arms too high
A19: Notes | B19: Move down to the ball on approach, keep hands firm, push don't swing
A20: Displayed Attributes | D20: Attributes to Progress
A21: =IF(B18="Beginner",Data!B15,IF(B18="Intermediate",Data!C15,IF(B18="Advanced",Data!D15,"No Rating"))) -> Confident at net; controls pace and placement; executes drop volleys and angled winners. | D21: =IF(B18="Beginner",Data!C15,IF(B18="Intermediate",Data!D15,"No Rating")) -> No Rating
A22: Attribute | B22: Level | C22: Rating (1-5) | D22: Strengths | E22: Weaknesses
A23: =Data!A16 -> Overhead Smash | B23: Advanced | C23: 3 - Competent
A24: Notes
A25: Displayed Attributes | D25: Attributes to Progress
A26: =IF(B23="Beginner",Data!B16,IF(B23="Intermediate",Data!C16,IF(B23="Advanced",Data!D16,"No Rating"))) -> Aggressive, accurate overheads; can handle defensive situations and chase tough lobs. | D26: =IF(B23="Beginner",Data!C16,IF(B23="Intermediate",Data!D16,"No Rating")) -> No Rating
A27: Attribute | B27: Level | C27: Rating (1-5) | D27: Strengths | E27: Weaknesses
A28: =Data!A17 -> Return of Serve | B28: Advanced | C28: 4 - Proficient
A29: Notes | B29: Split step as server strikes the ball, step into the ball and keep back swing short. Best return down the line or back at the server
A30: Displayed Attributes | D30: Attributes to Progress
A31: =IF(B28="Beginner",Data!B17,IF(B28="Intermediate",Data!C17,IF(B28="Advanced",Data!D17,"No Rating"))) -> Turns returns into offensive shots; anticipates serve patterns; controls direction and spin. | D31: =IF(B28="Beginner",Data!C17,IF(B28="Intermediate",Data!D17,"No Rating")) -> No Rating
A32: Attribute | B32: Level | C32: Rating (1-5) | D32: Strengths | E32: Weaknesses
A33: =Data!A18 -> Specialty Shots | B33: Beginner | C33: 2 - Developing
A34: Notes
A35: Displayed Attributes | D35: Attributes to Progress
A36: =IF(B33="Beginner",Data!B18,IF(B33="Intermediate",Data!C18,IF(B33="Advanced",Data!D18,"No Rating"))) -> Rarely attempted; inconsistent execution. | D36: =IF(B33="Beginner",Data!C18,IF(B33="Intermediate",Data!D18,"No Rating")) -> Uses drop shots and lobs occasionally; moderate success.

Sheet Serve & Return
A1: Serve & Return
A2: Attribute | B2: Level | C2: Rating (1-5) | D2: Strengths | E2: Weaknesses
A3: =Data!A21 -> Shot Selection | B3: Advanced | C3: 4 - Proficient | G3: First Serve Power & Accuracy
A4: Notes | G4: Second Serve Reliability
A5: Displayed Attributes | D5: Attributes to Progress | G5: Serve Variation
A6: =IF(B3="Beginner",Data!B42,IF(B3="Intermediate",Data!C42,IF(B3="Advanced",Data!D42,"No Rating"))) -> Powerful, accurate first serve with tactical placement. | D6: =IF(B3="Beginner",Data!C42,IF(B3="Intermediate",Data!D42,"No Rating")) -> No Rating | G6: Return Positioning
A7: Attribute | B7: Level | C7: Rating (1-5) | D7: Strengths | E7: Weaknesses | G7: Return Strategies
A8: =Data!A43 -> Second Serve Reliability | B8: Advanced | C8: 4 - Proficient
A9: Notes
A10: Displayed Attributes | D10: Attributes to Progress
A11: =IF(B8="Beginner",Data!B43,IF(B8="Intermediate",Data!C43,IF(B8="Advanced",Data!D43,"No Rating"))) -> Confident, consistent second serve under pressure. | D11: =IF(B8="Beginner",Data!C43,IF(B8="Intermediate",Data!D43,"No Rating")) -> No Rating
A12: Attribute | B12: Level | C12: Rating (1-5) | D12: Strengths | E12: Weaknesses
A13: =Data!A44 -> Serve Variation | B13: Advanced | C13: 4 - Proficient
A14: Notes
A15: Displayed Attributes | D15: Attributes to Progress
A16: =IF(B13="Beginner",Data!B44,IF(B13="Intermediate",Data!C44,IF(B13="Advanced",Data!D44,"No Rating"))) -> Regularly mixes spin, speed, and placement. | D16: =IF(B13="Beginner",Data!C44,IF(B13="Intermediate",Data!D44,"No Rating")) -> No Rating
A17: Attribute | B17: Level | C17: Rating (1-5) | D17: Strengths | E17: Weaknesses
A18: =Data!A45 -> Return Positioning | B18: Advanced | C18: 4 - Proficient
A19: Notes
A20: Displayed Attributes | D20: Attributes to Progress
A21: =IF(B18="Beginner",Data!B45,IF(B18="Intermediate",Data!C45,IF(B18="Advanced",Data!D45,"No Rating"))) -> Proactively positions based on server tendencies. | D21: =IF(B18="Beginner",Data!C45,IF(B18="Intermediate",Data!D45,"No Rating")) -> No Rating
A22: Attribute | B22: Level | C22: Rating (1-5) | D22: Strengths | E22: Weaknesses
A23: =Data!A46 -> Return Strategies | B23: Advanced | C23: 4 - Proficient
A24: Notes
A25: Displayed Attributes | D25: Attributes to Progress
A26: =IF(B23="Beginner",Data!B46,IF(B23="Intermediate",Data!C46,IF(B23="Advanced",Data!D46,"No Rating"))) -> Aggressively redirects or counterattacks serve. | D26: =IF(B23="Beginner",Data!C46,IF(B23="Intermediate",Data!D46,"No Rating")) -> No Rating

Sheet Footwork & Movement
A1: Footwork & Movement
A2: Attribute | B2: Level | C2: Rating (1-5) | D2: Strengths | E2: Weaknesses
A3: =Data!A35 -> Split-step Timing | B3: Intermediate | C3: 3 - Competent
A4: Notes
A5: Displayed Attributes | D5: Attributes to Progress
A6: =IF(B3="Beginner",Data!B35,IF(B3="Intermediate",Data!C35,IF(B3="Advanced",Data!D35,"No Rating"))) -> Uses split-step inconsistently; improving timing. | D6: =IF(B3="Beginner",Data!C35,IF(B3="Intermediate",Data!D35,"No Rating")) -> Consistent, well-timed split-step before every shot.
A7: Attribute | B7: Level | C7: Rating (1-5) | D7: Strengths | E7: Weaknesses
A8: =Data!A36 -> Recovery Steps | B8: Intermediate | C8: 3 - Competent
A9: Notes
A10: Displayed Attributes | D10: Attributes to Progress
A11: =IF(B8="Beginner",Data!B36,IF(B8="Intermediate",Data!C36,IF(B8="Advanced",Data!D36,"No Rating"))) -> Attempts recovery; sometimes late. | D11: =IF(B8="Beginner",Data!C36,IF(B8="Intermediate",Data!D36,"No Rating")) -> Quick, efficient recovery to ready position.
A12: Attribute | B12: Level | C12: Rating (1-5) | D12: Strengths | E12: Weaknesses
A13: =Data!A37 -> Lateral Movement | B13: Intermediate | C13: 4 - Proficient
A14: Notes
A15: Displayed Attributes | D15: Attributes to Progress
A16: =IF(B13="Beginner",Data!B37,IF(B13="Intermediate",Data!C37,IF(B13="Advanced",Data!D37,"No Rating"))) -> Covers baseline with moderate success. | D16: =IF(B13="Beginner",Data!C37,IF(B13="Intermediate",Data!D37,"No Rating")) -> Excellent lateral speed and balance.
A17: Attribute | B17: Level | C17: Rating (1-5) | D17: Strengths | E17: Weaknesses
A18: =Data!A38 -> Forward/Backward Movement | B18: Intermediate | C18: 2 - Developing
A19: Notes
A20: Displayed Attributes | D20: Attributes to Progress
A21: =IF(B18="Beginner",Data!B38,IF(B18="Intermediate",Data!C38,IF(B18="Advanced",Data!D38,"No Rating"))) -> Improved net approaches and drop shot retrieval. | D21: =IF(B18="Beginner",Data!C38,IF(B18="Intermediate",Data!D38,"No Rating")) -> Explosive forward movement; quick recovery backward.
A22: Attribute | B22: Level | C22: Rating (1-5) | D22: Strengths | E22: Weaknesses
A23: =Data!A39 -> Balance and Posture | B23: Intermediate | C23: 3 - Competent
A24: Notes
A25: Displayed Attributes | D25: Attributes to Progress
A26: =IF(B23="Beginner",Data!B39,IF(B23="Intermediate",Data!C39,IF(B23="Advanced",Data!D39,"No Rating"))) -> Improved posture; fewer off-balance errors. | D26: =IF(B23="Beginner",Data!C39,IF(B23="Intermediate",Data!D39,"No Rating")) -> Stable and balanced in all shot situations.

Sheet Tactical Awareness
A1: Tactical Awareness
A2: Attribute | B2: Level | C2: Rating (1-5) | D2: Strengths | E2: Weaknesses
A3: =Data!A21 -> Shot Selection | B3: Intermediate | C3: 4 - Proficient
A4: Notes
A5: Displayed Attributes | D5: Attributes to Progress
A6: =IF(B3="Beginner",Data!B21,IF(B3="Intermediate",Data!C21,IF(B3="Advanced",Data!D21,"No Rating"))) -> Understands basic patterns; improving decision-making. | D6: =IF(B3="Beginner",Data!C21,IF(B3="Intermediate",Data!D21,"No Rating")) -> Consistently chooses high-percentage shots; adapts to situations.
A7: Attribute | B7: Level | C7: Rating (1-5) | D7: Strengths | E7: Weaknesses
A8: =Data!A22 -> Point Construction | B8: Beginner | C8: 1 - Basic
A9: Notes
A10: Displayed Attributes | D10: Attributes to Progress
A11: =IF(B8="Beginner",Data!B22,IF(B8="Intermediate",Data!C22,IF(B8="Advanced",Data!D22,"No Rating"))) -> Plays one-shot tennis; lacks planning. | D11: =IF(B8="Beginner",Data!C22,IF(B8="Intermediate",Data!D22,"No Rating")) -> Attempts to build points; uses strengths occasionally.
A12: Attribute | B12: Level | C12: Rating (1-5) | D12: Strengths | E12: Weaknesses
A13: =Data!A23 -> Adapting to Opponent | B13: Beginner | C13: 2 - Developing
A14: Notes
A15: Displayed Attributes | D15: Attributes to Progress
A16: =IF(B13="Beginner",Data!B23,IF(B13="Intermediate",Data!C23,IF(B13="Advanced",Data!D23,"No Rating"))) -> Plays same style regardless of opponent. | D16: =IF(B13="Beginner",Data!C23,IF(B13="Intermediate",Data!D23,"No Rating")) -> Recognizes opponent tendencies; adjusts occasionally.
A17: Attribute | B17: Level | C17: Rating (1-5) | D17: Strengths | E17: Weaknesses
A18: =Data!A24 -> Playing to Surfaces | B18: Beginner | C18: 2 - Developing
A19: Notes
A20: Displayed Attributes | D20: Attributes to Progress
A21: =IF(B18="Beginner",Data!B24,IF(B18="Intermediate",Data!C24,IF(B18="Advanced",Data!D24,"No Rating"))) -> No adjustment to surface differences. | D21: =IF(B18="Beginner",Data!C24,IF(B18="Intermediate",Data!D24,"No Rating")) -> Basic understanding of surface impact on play.
A22: Attribute | B22: Level | C22: Rating (1-5) | D22: Strengths | E22: Weaknesses
A23: =Data!A25 -> Doubles Tactics | B23: Beginner | C23: 2 - Developing
A24: Notes
A25: Displayed Attributes | D25: Attributes to Progress
A26: =IF(B23="Beginner",Data!B25,IF(B23="Intermediate",Data!C25,IF(B23="Advanced",Data!D25,"No Rating"))) -> Limited understanding of positioning and roles. | D26: =IF(B23="Beginner",Data!C25,IF(B23="Intermediate",Data!D25,"No Rating")) -> Understands basic formations and communication.

Sheet Creativity & Variety
A1: Creativity & Variety
A2: Attribute | B2: Level | C2: Rating (1-5) | D2: Strengths | E2: Weaknesses
A3: =Data!A91 -> Developing Spins | B3: Beginner | C3: 4 - Proficient | G3: First Serve Power & Accuracy
A4: Notes | G4: Second Serve Reliability
A5: Displayed Attributes | D5: Attributes to Progress | G5: Serve Variation
A6: =IF(B3="Beginner",Data!B91,IF(B3="Intermediate",Data!C91,IF(B3="Advanced",Data!D91,"No Rating"))) -> Limited spin control. | D6: =IF(B3="Beginner",Data!C91,IF(B3="Intermediate",Data!D91,"No Rating")) -> Uses topspin and slice occasionally. | G6: Return Positioning
A7: Attribute | B7: Level | C7: Rating (1-5) | D7: Strengths | E7: Weaknesses | G7: Return Strategies
A8: =Data!A92 -> Using Angles | B8: Beginner | C8: 1 - Basic
A9: Notes
A10: Displayed Attributes | D10: Attributes to Progress
A11: =IF(B8="Beginner",Data!B92,IF(B8="Intermediate",Data!C92,IF(B8="Advanced",Data!D92,"No Rating"))) -> Plays mostly down the middle. | D11: =IF(B8="Beginner",Data!C92,IF(B8="Intermediate",Data!D92,"No Rating")) -> Attempts cross-court angles.
A12: Attribute | B12: Level | C12: Rating (1-5) | D12: Strengths | E12: Weaknesses
A13: =Data!A93 -> Improvisation | B13: Beginner | C13: 2 - Developing
A14: Notes
A15: Displayed Attributes | D15: Attributes to Progress
A16: =IF(B13="Beginner",Data!B93,IF(B13="Intermediate",Data!C93,IF(B13="Advanced",Data!D93,"No Rating"))) -> Struggles outside structured play. | D16: =IF(B13="Beginner",Data!C93,IF(B13="Intermediate",Data!D93,"No Rating")) -> Occasionally improvises under pressure.
A17: Attribute | B17: Level | C17: Rating (1-5) | D17: Strengths | E17: Weaknesses
A18: =Data!A94 -> Trick Shots | B18: Beginner | C18: 2 - Developing
A19: Notes
A20: Displayed Attributes | D20: Attributes to Progress
A21: =IF(B18="Beginner",Data!B94,IF(B18="Intermediate",Data!C94,IF(B18="Advanced",Data!D94,"No Rating"))) -> Avoids or misuses trick shots. | D21: =IF(B18="Beginner",Data!C94,IF(B18="Intermediate",Data!D94,"No Rating")) -> Uses for fun or surprise.
A22: Attribute | B22: Level | C22: Rating (1-5) | D22: Strengths | E22: Weaknesses
A23: =Data!A95 -> Variety in Rally Play | B23: Beginner | C23: 2 - Developing
A24: Notes
A25: Displayed Attributes | D25: Attributes to Progress
A26: =IF(B23="Beginner",Data!B95,IF(B23="Intermediate",Data!C95,IF(B23="Advanced",Data!D95,"No Rating"))) -> One-dimensional rallies. | D26: =IF(B23="Beginner",Data!C95,IF(B23="Intermediate",Data!D95,"No Rating")) -> Mixes pace and direction occasionally.

Sheet Match Strategy
A1: Match Strategy
A2: Attribute | B2: Level | C2: Rating (1-5) | D2: Strengths | E2: Weaknesses
A3: =Data!A56 -> Pre-match Planning | B3: Beginner | C3: 4 - Proficient | G3: First Serve Power & Accuracy
A4: Notes | G4: Second Serve Reliability
A5: Displayed Attributes | D5: Attributes to Progress | G5: Serve Variation
A6: =IF(B3="Beginner",Data!B56,IF(B3="Intermediate",Data!C56,IF(B3="Advanced",Data!D56,"No Rating"))) -> No plan; relies on instinct. | D6: =IF(B3="Beginner",Data!C56,IF(B3="Intermediate",Data!D56,"No Rating")) -> Basic plan based on past matches. | G6: Return Positioning
A7: Attribute | B7: Level | C7: Rating (1-5) | D7: Strengths | E7: Weaknesses | G7: Return Strategies
A8: =Data!A57 -> In-match Adjustments | B8: Beginner | C8: 1 - Basic
A9: Notes
A10: Displayed Attributes | D10: Attributes to Progress
A11: =IF(B8="Beginner",Data!B57,IF(B8="Intermediate",Data!C57,IF(B8="Advanced",Data!D57,"No Rating"))) -> Sticks to one strategy. | D11: =IF(B8="Beginner",Data!C57,IF(B8="Intermediate",Data!D57,"No Rating")) -> Attempts adjustments when losing.
A12: Attribute | B12: Level | C12: Rating (1-5) | D12: Strengths | E12: Weaknesses
A13: =Data!A58 -> Surface-specific Strategies | B13: Beginner | C13: 2 - Developing
A14: Notes
A15: Displayed Attributes | D15: Attributes to Progress
A16: =IF(B13="Beginner",Data!B58,IF(B13="Intermediate",Data!C58,IF(B13="Advanced",Data!D58,"No Rating"))) -> Same tactics on all surfaces. | D16: =IF(B13="Beginner",Data!C58,IF(B13="Intermediate",Data!D58,"No Rating")) -> Adjusts slightly for surface.
A17: Attribute | B17: Level | C17: Rating (1-5) | D17: Strengths | E17: Weaknesses
A18: =Data!A59 -> Singles vs Doubles Approaches | B18: Beginner | C18: 2 - Developing
A19: Notes
A20: Displayed Attributes | D20: Attributes to Progress
A21: =IF(B18="Beginner",Data!B59,IF(B18="Intermediate",Data!C59,IF(B18="Advanced",Data!D59,"No Rating"))) -> Same style in both formats. | D21: =IF(B18="Beginner",Data!C59,IF(B18="Intermediate",Data!D59,"No Rating")) -> Understands basic differences.
A22: Attribute | B22: Level | C22: Rating (1-5) | D22: Strengths | E22: Weaknesses
A23: =Data!A60 -> Closing Out Matches | B23: Beginner | C23: 2 - Developing
A24: Notes
A25: Displayed Attributes | D25: Attributes to Progress
A26: =IF(B23="Beginner",Data!B60,IF(B23="Intermediate",Data!C60,IF(B23="Advanced",Data!D60,"No Rating"))) -> Struggles to finish matches. | D26: =IF(B23="Beginner",Data!C60,IF(B23="Intermediate",Data!D60,"No Rating")) -> Can close with effort and focus.

Sheet Competitive Experience
A1: Competitive Experience
A2: Attribute | B2: Level | C2: Rating (1-5) | D2: Strengths | E2: Weaknesses
A3: =Data!A63 -> Tournament Exposure | B3: Beginner | C3: 4 - Proficient | G3: First Serve Power & Accuracy
A4: Notes | G4: Second Serve Reliability
A5: Displayed Attributes | D5: Attributes to Progress | G5: Serve Variation
A6: =IF(B3="Beginner",Data!B63,IF(B3="Intermediate",Data!C63,IF(B3="Advanced",Data!D63,"No Rating"))) -> Limited match play experience. | D6: =IF(B3="Beginner",Data!C63,IF(B3="Intermediate",Data!D63,"No Rating")) -> Plays local tournaments occasionally. | G6: Return Positioning
A7: Attribute | B7: Level | C7: Rating (1-5) | D7: Strengths | E7: Weaknesses | G7: Return Strategies
A8: =Data!A64 -> Match-play Practice | B8: Beginner | C8: 1 - Basic
A9: Notes
A10: Displayed Attributes | D10: Attributes to Progress
A11: =IF(B8="Beginner",Data!B64,IF(B8="Intermediate",Data!C64,IF(B8="Advanced",Data!D64,"No Rating"))) -> Rarely plays practice matches. | D11: =IF(B8="Beginner",Data!C64,IF(B8="Intermediate",Data!D64,"No Rating")) -> Plays matches weekly.
A12: Attribute | B12: Level | C12: Rating (1-5) | D12: Strengths | E12: Weaknesses
A13: =Data!A65 -> Handling Pressure Situations | B13: Beginner | C13: 2 - Developing
A14: Notes
A15: Displayed Attributes | D15: Attributes to Progress
A16: =IF(B13="Beginner",Data!B65,IF(B13="Intermediate",Data!C65,IF(B13="Advanced",Data!D65,"No Rating"))) -> Struggles in tiebreaks or close sets. | D16: =IF(B13="Beginner",Data!C65,IF(B13="Intermediate",Data!D65,"No Rating")) -> Improving under pressure.
A17: Attribute | B17: Level | C17: Rating (1-5) | D17: Strengths | E17: Weaknesses
A18: =Data!A66 -> Learning from Wins/Losses | B18: Beginner | C18: 2 - Developing
A19: Notes
A20: Displayed Attributes | D20: Attributes to Progress
A21: =IF(B18="Beginner",Data!B66,IF(B18="Intermediate",Data!C66,IF(B18="Advanced",Data!D66,"No Rating"))) -> Repeats same mistakes. | D21: =IF(B18="Beginner",Data!C66,IF(B18="Intermediate",Data!D66,"No Rating")) -> Reflects occasionally on outcomes.
A22: Attribute | B22: Level | C22: Rating (1-5) | D22: Strengths | E22: Weaknesses
A23: =Data!A67 -> Match Consistency | B23: Beginner | C23: 2 - Developing
A24: Notes
A25: Displayed Attributes | D25: Attributes to Progress
A26: =IF(B23="Beginner",Data!B67,IF(B23="Intermediate",Data!C67,IF(B23="Advanced",Data!D67,"No Rating"))) -> Inconsistent performance. | D26: =IF(B23="Beginner",Data!C67,IF(B23="Intermediate",Data!D67,"No Rating")) -> Plays well in patches.

Sheet Physical Fitness
A1: Physical Fitness
A2: Attribute | B2: Level | C2: Rating (1-5) | D2: Strengths | E2: Weaknesses
A3: =Data!A28 -> Strength | B3: Beginner | C3: 4 - Proficient
A4: Notes
A5: Displayed Attributes | D5: Attributes to Progress
A6: =IF(B3="Beginner",Data!B28,IF(B3="Intermediate",Data!C28,IF(B3="Advanced",Data!D28,"No Rating"))) -> Limited strength; struggles with power generation. | D6: =IF(B3="Beginner",Data!C28,IF(B3="Intermediate",Data!D28,"No Rating")) -> Developing core and leg strength; improved shot stability.
A7: Attribute | B7: Level | C7: Rating (1-5) | D7: Strengths | E7: Weaknesses
A8: =Data!A29 -> Endurance | B8: Beginner | C8: 1 - Basic
A9: Notes
A10: Displayed Attributes | D10: Attributes to Progress
A11: =IF(B8="Beginner",Data!B29,IF(B8="Intermediate",Data!C29,IF(B8="Advanced",Data!D29,"No Rating"))) -> Fatigues quickly; inconsistent performance. | D11: =IF(B8="Beginner",Data!C28,IF(B8="Intermediate",Data!D28,"No Rating")) -> Developing core and leg strength; improved shot stability.
A12: Attribute | B12: Level | C12: Rating (1-5) | D12: Strengths | E12: Weaknesses
A13: =Data!A30 -> Speed | B13: Beginner | C13: 2 - Developing
A14: Notes
A15: Displayed Attributes | D15: Attributes to Progress
A16: =IF(B13="Beginner",Data!B30,IF(B13="Intermediate",Data!C30,IF(B13="Advanced",Data!D30,"No Rating"))) -> Slow reactions; difficulty reaching wide balls. | D16: =IF(B13="Beginner",Data!C30,IF(B13="Intermediate",Data!D30,"No Rating")) -> Improved court coverage; decent acceleration.
A17: Attribute | B17: Level | C17: Rating (1-5) | D17: Strengths | E17: Weaknesses
A18: =Data!A31 -> Agility | B18: Beginner | C18: 2 - Developing
A19: Notes
A20: Displayed Attributes | D20: Attributes to Progress
A21: =IF(B18="Beginner",Data!B31,IF(B18="Intermediate",Data!C31,IF(B18="Advanced",Data!D31,"No Rating"))) -> Struggles with direction changes. | D21: =IF(B18="Beginner",Data!C31,IF(B18="Intermediate",Data!D31,"No Rating")) -> Can change direction with moderate control.
A22: Attribute | B22: Level | C22: Rating (1-5) | D22: Strengths | E22: Weaknesses
A23: =Data!A32 -> Flexibility & Mobility | B23: Beginner | C23: 2 - Developing
A24: Notes
A25: Displayed Attributes | D25: Attributes to Progress
A26: =IF(B23="Beginner",Data!B32,IF(B23="Intermediate",Data!C32,IF(B23="Advanced",Data!D32,"No Rating"))) -> Limited range of motion; injury risk. | D26: =IF(B23="Beginner",Data!C32,IF(B23="Intermediate",Data!D32,"No Rating")) -> Improved flexibility; fewer movement restrictions.

Sheet Mental Toughness
A1: Mental Toughness
A2: Attribute | B2: Level | C2: Rating (1-5) | D2: Strengths | E2: Weaknesses
A3: =Data!A49 -> Focus and Concentration | B3: Beginner | C3: 4 - Proficient | G3: First Serve Power & Accuracy
A4: Notes | G4: Second Serve Reliability
A5: Displayed Attributes | D5: Attributes to Progress | G5: Serve Variation
A6: =IF(B3="Beginner",Data!B49,IF(B3="Intermediate",Data!C49,IF(B3="Advanced",Data!D49,"No Rating"))) -> Easily distracted; loses focus mid-point. | D6: =IF(B3="Beginner",Data!C49,IF(B3="Intermediate",Data!D49,"No Rating")) -> Stays focused for most of match. | G6: Return Positioning
A7: Attribute | B7: Level | C7: Rating (1-5) | D7: Strengths | E7: Weaknesses | G7: Return Strategies
A8: =Data!A50 -> Confidence Under Pressure | B8: Beginner | C8: 1 - Basic
A9: Notes
A10: Displayed Attributes | D10: Attributes to Progress
A11: =IF(B8="Beginner",Data!B50,IF(B8="Intermediate",Data!C50,IF(B8="Advanced",Data!D50,"No Rating"))) -> Doubts self in tight moments. | D11: =IF(B8="Beginner",Data!C50,IF(B8="Intermediate",Data!D50,"No Rating")) -> Occasionally confident under pressure.
A12: Attribute | B12: Level | C12: Rating (1-5) | D12: Strengths | E12: Weaknesses
A13: =Data!A51 -> Emotional Control | B13: Beginner | C13: 2 - Developing
A14: Notes
A15: Displayed Attributes | D15: Attributes to Progress
A16: =IF(B13="Beginner",Data!B51,IF(B13="Intermediate",Data!C51,IF(B13="Advanced",Data!D51,"No Rating"))) -> Frequent frustration or visible emotion. | D16: =IF(B13="Beginner",Data!C51,IF(B13="Intermediate",Data!D51,"No Rating")) -> Manages emotions with effort.
A17: Attribute | B17: Level | C17: Rating (1-5) | D17: Strengths | E17: Weaknesses
A18: =Data!A52 -> Resilience | B18: Beginner | C18: 2 - Developing
A19: Notes
A20: Displayed Attributes | D20: Attributes to Progress
A21: =IF(B18="Beginner",Data!B52,IF(B18="Intermediate",Data!C52,IF(B18="Advanced",Data!D52,"No Rating"))) -> Gives up after mistakes or losses. | D21: =IF(B18="Beginner",Data!C52,IF(B18="Intermediate",Data!D52,"No Rating")) -> Recovers slowly from setbacks.
A22: Attribute | B22: Level | C22: Rating (1-5) | D22: Strengths | E22: Weaknesses
A23: =Data!A53 -> Match Intensity | B23: Beginner | C23: 2 - Developing
A24: Notes
A25: Displayed Attributes | D25: Attributes to Progress
A26: =IF(B23="Beginner",Data!B53,IF(B23="Intermediate",Data!C53,IF(B23="Advanced",Data!D53,"No Rating"))) -> Low energy; inconsistent effort. | D26: =IF(B23="Beginner",Data!C53,IF(B23="Intermediate",Data!D53,"No Rating")) -> Moderate intensity; fades at times.

Sheet Recovery & Injury Prevention
A1: Recovery & Injury Prevention
A2: Attribute | B2: Level | C2: Rating (1-5) | D2: Strengths | E2: Weaknesses
A3: =Data!A70 -> Rest and Sleep | B3: Beginner | C3: 4 - Proficient | G3: First Serve Power & Accuracy
A4: Notes | G4: Second Serve Reliability
A5: Displayed Attributes | D5: Attributes to Progress | G5: Serve Variation
A6: =IF(B3="Beginner",Data!B70,IF(B3="Intermediate",Data!C70,IF(B3="Advanced",Data!D70,"No Rating"))) -> Irregular sleep; poor recovery. | D6: =IF(B3="Beginner",Data!C70,IF(B3="Intermediate",Data!D70,"No Rating")) -> Improving rest habits. | G6: Return Positioning
A7: Attribute | B7: Level | C7: Rating (1-5) | D7: Strengths | E7: Weaknesses | G7: Return Strategies
A8: =Data!A71 -> Nutrition and Hydration | B8: Beginner | C8: 1 - Basic
A9: Notes
A10: Displayed Attributes | D10: Attributes to Progress
A11: =IF(B8="Beginner",Data!B71,IF(B8="Intermediate",Data!C71,IF(B8="Advanced",Data!D71,"No Rating"))) -> Unaware of fueling needs. | D11: =IF(B8="Beginner",Data!C71,IF(B8="Intermediate",Data!D71,"No Rating")) -> Basic hydration and nutrition habits.
A12: Attribute | B12: Level | C12: Rating (1-5) | D12: Strengths | E12: Weaknesses
A13: =Data!A72 -> Warm-up/Cool-down | B13: Beginner | C13: 2 - Developing
A14: Notes
A15: Displayed Attributes | D15: Attributes to Progress
A16: =IF(B13="Beginner",Data!B72,IF(B13="Intermediate",Data!C72,IF(B13="Advanced",Data!D72,"No Rating"))) -> Skips or rushes warm-up. | D16: =IF(B13="Beginner",Data!C72,IF(B13="Intermediate",Data!D72,"No Rating")) -> Performs basic routines.
A17: Attribute | B17: Level | C17: Rating (1-5) | D17: Strengths | E17: Weaknesses
A18: =Data!A73 -> Prehab Exercises | B18: Beginner | C18: 2 - Developing
A19: Notes
A20: Displayed Attributes | D20: Attributes to Progress
A21: =IF(B18="Beginner",Data!B73,IF(B18="Intermediate",Data!C73,IF(B18="Advanced",Data!D73,"No Rating"))) -> Does not perform injury prevention. | D21: =IF(B18="Beginner",Data!C73,IF(B18="Intermediate",Data!D73,"No Rating")) -> Occasional prehab work.
A22: Attribute | B22: Level | C22: Rating (1-5) | D22: Strengths | E22: Weaknesses
A23: =Data!A74 -> Injury Management Awareness | B23: Beginner | C23: 2 - Developing
A24: Notes
A25: Displayed Attributes | D25: Attributes to Progress
A26: =IF(B23="Beginner",Data!B74,IF(B23="Intermediate",Data!C74,IF(B23="Advanced",Data!D74,"No Rating"))) -> Plays through pain; lacks awareness. | D26: =IF(B23="Beginner",Data!C74,IF(B23="Intermediate",Data!D74,"No Rating")) -> Reports issues; seeks help.

Sheet Communication & Self-Reflection
A1: Communication & Self-Reflection
A2: Attribute | B2: Level | C2: Rating (1-5) | D2: Strengths | E2: Weaknesses
A3: =Data!A77 -> Player–Coach Dialogue | B3: Beginner | C3: 4 - Proficient | G3: First Serve Power & Accuracy
A4: Notes | G4: Second Serve Reliability
A5: Displayed Attributes | D5: Attributes to Progress | G5: Serve Variation
A6: =IF(B3="Beginner",Data!B77,IF(B3="Intermediate",Data!C77,IF(B3="Advanced",Data!D77,"No Rating"))) -> Minimal communication. | D6: =IF(B3="Beginner",Data!C77,IF(B3="Intermediate",Data!D77,"No Rating")) -> Shares feedback occasionally. | G6: Return Positioning
A7: Attribute | B7: Level | C7: Rating (1-5) | D7: Strengths | E7: Weaknesses | G7: Return Strategies
A8: =Data!A78 -> Journaling/Match Notes | B8: Beginner | C8: 1 - Basic
A9: Notes
A10: Displayed Attributes | D10: Attributes to Progress
A11: =IF(B8="Beginner",Data!B78,IF(B8="Intermediate",Data!C78,IF(B8="Advanced",Data!D78,"No Rating"))) -> Does not reflect on matches. | D11: =IF(B8="Beginner",Data!C78,IF(B8="Intermediate",Data!D78,"No Rating")) -> Occasional notes or journaling.
A12: Attribute | B12: Level | C12: Rating (1-5) | D12: Strengths | E12: Weaknesses
A13: =Data!A79 -> Video Analysis | B13: Beginner | C13: 2 - Developing
A14: Notes
A15: Displayed Attributes | D15: Attributes to Progress
A16: =IF(B13="Beginner",Data!B79,IF(B13="Intermediate",Data!C79,IF(B13="Advanced",Data!D79,"No Rating"))) -> Rarely watches footage. | D16: =IF(B13="Beginner",Data!C79,IF(B13="Intermediate",Data!D79,"No Rating")) -> Watches with coach occasionally.
A17: Attribute | B17: Level | C17: Rating (1-5) | D17: Strengths | E17: Weaknesses
A18: =Data!A80 -> Goal Setting | B18: Beginner | C18: 2 - Developing
A19: Notes
A20: Displayed Attributes | D20: Attributes to Progress
A21: =IF(B18="Beginner",Data!B80,IF(B18="Intermediate",Data!C80,IF(B18="Advanced",Data!D80,"No Rating"))) -> No clear goals. | D21: =IF(B18="Beginner",Data!C80,IF(B18="Intermediate",Data!D80,"No Rating")) -> Sets short-term goals.
A22: Attribute | B22: Level | C22: Rating (1-5) | D22: Strengths | E22: Weaknesses
A23: =Data!A81 -> Peer Feedback | B23: Beginner | C23: 2 - Developing
A24: Notes
A25: Displayed Attributes | D25: Attributes to Progress
A26: =IF(B23="Beginner",Data!B81,IF(B23="Intermediate",Data!C81,IF(B23="Advanced",Data!D81,"No Rating"))) -> Avoids feedback. | D26: =IF(B23="Beginner",Data!C81,IF(B23="Intermediate",Data!D81,"No Rating")) -> Accepts feedback when prompted.

Sheet Lifestyle & Discipline
A1: Lifestyle & Discipline
A2: Attribute | B2: Level | C2: Rating (1-5) | D2: Strengths | E2: Weaknesses
A3: =Data!A84 -> Time Management | B3: Beginner | C3: 4 - Proficient | G3: First Serve Power & Accuracy
A4: Notes | G4: Second Serve Reliability
A5: Displayed Attributes | D5: Attributes to Progress | G5: Serve Variation
A6: =IF(B3="Beginner",Data!B84,IF(B3="Intermediate",Data!C84,IF(B3="Advanced",Data!D84,"No Rating"))) -> Often late or unprepared. | D6: =IF(B3="Beginner",Data!C84,IF(B3="Intermediate",Data!D84,"No Rating")) -> Improving punctuality and planning. | G6: Return Positioning
A7: Attribute | B7: Level | C7: Rating (1-5) | D7: Strengths | E7: Weaknesses | G7: Return Strategies
A8: =Data!A85 -> Sleep Hygiene | B8: Beginner | C8: 1 - Basic
A9: Notes
A10: Displayed Attributes | D10: Attributes to Progress
A11: =IF(B8="Beginner",Data!B85,IF(B8="Intermediate",Data!C85,IF(B8="Advanced",Data!D85,"No Rating"))) -> Irregular sleep schedule. | D11: =IF(B8="Beginner",Data!C85,IF(B8="Intermediate",Data!D85,"No Rating")) -> Basic awareness of sleep needs.
A12: Attribute | B12: Level | C12: Rating (1-5) | D12: Strengths | E12: Weaknesses
A13: =Data!A86 -> Nutrition Habits | B13: Beginner | C13: 2 - Developing
A14: Notes
A15: Displayed Attributes | D15: Attributes to Progress
A16: =IF(B13="Beginner",Data!B86,IF(B13="Intermediate",Data!C86,IF(B13="Advanced",Data!D86,"No Rating"))) -> Poor eating habits. | D16: =IF(B13="Beginner",Data!C86,IF(B13="Intermediate",Data!D86,"No Rating")) -> Improving food choices.
A17: Attribute | B17: Level | C17: Rating (1-5) | D17: Strengths | E17: Weaknesses
A18: =Data!A87 -> Professionalism | B18: Beginner | C18: 2 - Developing
A19: Notes
A20: Displayed Attributes | D20: Attributes to Progress
A21: =IF(B18="Beginner",Data!B87,IF(B18="Intermediate",Data!C87,IF(B18="Advanced",Data!D87,"No Rating"))) -> Casual attitude toward training. | D21: =IF(B18="Beginner",Data!C87,IF(B18="Intermediate",Data!D87,"No Rating")) -> Takes training seriously.
A22: Attribute | B22: Level | C22: Rating (1-5) | D22: Strengths | E22: Weaknesses
A23: =Data!A88 -> Routine Consistency | B23: Beginner | C23: 2 - Developing
A24: Notes
A25: Displayed Attributes | D25: Attributes to Progress
A26: =IF(B23="Beginner",Data!B88,IF(B23="Intermediate",Data!C88,IF(B23="Advanced",Data!D88,"No Rating"))) -> Inconsistent routines. | D26: =IF(B23="Beginner",Data!C88,IF(B23="Intermediate",Data!D88,"No Rating")) -> Developing habits.

Sheet Data
A1: Rating | B1: Sex | D1: Level
A2: 1 - Basic | B2: Male | D2: Beginner
A3: 2 - Developing | B3: Female | D3: Intermediate
A4: 3 - Competent | D4: Advanced
A5: 4 - Proficient
A6: 5 - Mastery
A11: Technical Skills | B11: Beginner Expectation | C11: Intermediate Expectation | D11: Advanced Expectation
A12: Forehand | B12: Basic grip and swing; inconsistent contact; struggles with depth and spin. | C12: Reliable topspin; can vary direction; moderate pace; occasional use of slice. | D12: Generates pace and spin at will; precise placement; uses inside-out/inside-in variations strategically.
A13: Backhand | B13: Limited control; often defensive; inconsistent two-handed or slice. | C13: Solid two-handed drive; reliable slice; can rally consistently cross-court. | D13: Offensive weapon; mixes drive and slice seamlessly; controls angles and depth.
A14: Serve | B14: Basic motion; inconsistent toss; limited power; double faults common. | C14: Reliable first serve; developing second serve spin; can place to corners. | D14: Variety of serves (flat, slice, kick); tactical placement; uses serve to set up points.
A15: Volley | B15: Awkward positioning; inconsistent contact; struggles with timing. | C15: Competent forehand/backhand volleys; can finish points at net; decent touch. | D15: Confident at net; controls pace and placement; executes drop volleys and angled winners.
A16: Overhead Smash | B16: Difficulty judging lobs; inconsistent execution. | C16: Reliable overheads; can finish points when set up well. | D16: Aggressive, accurate overheads; can handle defensive situations and chase tough lobs.
A17: Return of Serve | B17: Defensive block; struggles with timing; inconsistent depth. | C17: Solid returns against medium pace; can neutralize first serves; aggressive on second serves. | D17: Turns returns into offensive shots; anticipates serve patterns; controls direction and spin.
A18: Specialty Shots | B18: Rarely attempted; inconsistent execution. | C18: Uses drop shots and lobs occasionally; moderate success. | D18: Confident variety; uses specialty shots tactically to disrupt opponents.
A20: Tactical Awareness | B20: Beginner Expectation | C20: Intermediate Expectation | D20: Advanced Expectation
A21: Shot Selection | B21: Limited awareness; reactive choices; frequent errors. | C21: Understands basic patterns; improving decision-making. | D21: Consistently chooses high-percentage shots; adapts to situations.
A22: Point Construction | B22: Plays one-shot tennis; lacks planning. | C22: Attempts to build points; uses strengths occasionally. | D22: Constructs points with purpose; exploits opponent weaknesses.
A23: Adapting to Opponent | B23: Plays same style regardless of opponent. | C23: Recognizes opponent tendencies; adjusts occasionally. | D23: Consistently adapts tactics based on opponent’s strengths/weaknesses.
... A95: Variety in Rally Play | B95: One-dimensional rallies. | C95: Mixes pace and direction occasionally. | D95: Constantly varies rhythm, spin, and placement.

Sheet MASTER SHEET
A1: Attribute | B1: Level | C1: Rating (1-5) | D1: Strengths | E1: Weaknesses
A2: Forehand | B2: Beginner | C2: 4 - Proficient
A3: Notes
A4: Displayed Attributes | D4: Attributes to Progress
A5: =IF(B2="Beginner",Data!B12,IF(B2="Intermediate",Data!C12,IF(B2="Advanced",Data!D12,"No Rating"))) -> Basic grip and swing; inconsistent contact; struggles with depth and spin. | D5: =IF(B2="Beginner",Data!C12,IF(B2="Intermediate",Data!D12,"No Rating")) -> Reliable topspin; can vary direction; moderate pace; occasional use of slice.
A6: Attribute | B6: Level | C6: Rating (1-5) | D6: Strengths | E6: Weaknesses
A7: Backhand | B7: Beginner | C7: 1 - Basic
A8: Notes
A9: Displayed Attributes | D9: Attributes to Progress
A10: =IF(B7="Beginner",Data!B13,IF(B7="Intermediate",Data!C13,IF(B7="Advanced",Data!D13,"No Rating"))) -> Limited control; often defensive; inconsistent two-handed or slice. | D10: =IF(B7="Beginner",Data!C13,IF(B7="Intermediate",Data!D13,"No Rating")) -> Solid two-handed drive; reliable slice; can rally consistently cross-court.
A11: Attribute | B11: Level | C11: Rating (1-5) | D11: Strengths | E11: Weaknesses
A12: Serve | B12: Beginner | C12: 2 - Developing
A13: Notes
A14: Displayed Attributes | D14: Attributes to Progress
A15: =IF(B12="Beginner",Data!B14,IF(B12="Intermediate",Data!C14,IF(B12="Advanced",Data!D14,"No Rating"))) -> Basic motion; inconsistent toss; limited power; double faults common. | D15: =IF(B12="Beginner",Data!C14,IF(B12="Intermediate",Data!D14,"No Rating")) -> Reliable first serve; developing second serve spin; can place to corners.
A16: Attribute | B16: Level | C16: Rating (1-5) | D16: Strengths | E16: Weaknesses
A17: Volley | B17: Beginner | C17: 2 - Developing
A18: Notes
A19: Displayed Attributes | D19: Attributes to Progress
A20: =IF(B17="Beginner",Data!B15,IF(B17="Intermediate",Data!C15,IF(B17="Advanced",Data!D15,"No Rating"))) -> Awkward positioning; inconsistent contact; struggles with timing. | D20: =IF(B17="Beginner",Data!C15,IF(B17="Intermediate",Data!D15,"No Rating")) -> Competent forehand/backhand volleys; can finish points at net; decent touch.
A21: Attribute | B21: Level | C21: Rating (1-5) | D21: Strengths | E21: Weaknesses
A22: Overhead Smash | B22: Beginner | C22: 2 - Developing
A23: Notes
A24: Displayed Attributes | D24: Attributes to Progress
A25: =IF(B22="Beginner",Data!B16,IF(B22="Intermediate",Data!C16,IF(B22="Advanced",Data!D16,"No Rating"))) -> Difficulty judging lobs; inconsistent execution. | D25: =IF(B22="Beginner",Data!C16,IF(B22="Intermediate",Data!D16,"No Rating")) -> Reliable overheads; can finish points when set up well.
A26: Attribute | B26: Level | C26: Rating (1-5) | D26: Strengths | E26: Weaknesses
A27: Return of Serve | B27: Beginner | C27: 2 - Developing
A28: Notes
A29: Displayed Attributes | D29: Attributes to Progress
A30: =IF(B27="Beginner",Data!B17,IF(B27="Intermediate",Data!C17,IF(B27="Advanced",Data!D17,"No Rating"))) -> Defensive block; struggles with timing; inconsistent depth. | D30: =IF(B27="Beginner",Data!C17,IF(B27="Intermediate",Data!D17,"No Rating")) -> Solid returns against medium pace; can neutralize first serves; aggressive on second serves.
A31: Attribute | B31: Level | C31: Rating (1-5) | D31: Strengths | E31: Weaknesses
A32: Return of Serve | B32: Beginner | C32: 2 - Developing
A33: Notes
A34: Displayed Attributes | D34: Attributes to Progress
A35: =IF(B32="Beginner",Data!B18,IF(B32="Intermediate",Data!C18,IF(B32="Advanced",Data!D18,"No Rating"))) -> Rarely attempted; inconsistent execution. | D35: =IF(B32="Beginner",Data!C18,IF(B32="Intermediate",Data!D18,"No Rating")) -> Uses drop shots and lobs occasionally; moderate success.
